Workbook

Sheet Rules
A1: ID | B1: System | C1: Component / pattern | D1: Rule (paraphrased) | E1: Class | F1: Checked by existing tool? | G1: Expressible in draft schema | H1: Notes | I1: Source
A2: R001 | B2: Primer | C2: Button | D2: Only one primary button per page where possible | E2: S | F2: none | G2: yes | H2: Cardinality, scope=page | I2: https://primer.style/product/components/button/guidelines/
A3: R002 | B3: Primer | C3: Button | D3: Never more than one primary button in a group of buttons | E3: S | F3: none | G3: yes | H3: Cardinality, scope=group | I3: https://primer.style/product/components/button/guidelines/
A4: R003 | B4: Primer | C4: Button | D4: Danger variant should normally prompt a confirmation dialog | E4: S | F4: none | G4: yes | H4: Accompaniment: danger trigger requires confirmation | I4: https://primer.style/product/components/button/guidelines/
A5: R004 | B5: Primer | C5: Button | D5: Labels must not contain line breaks | E5: P | F5: none | G5: yes | H5: Property: no newline in label | I5: https://primer.style/product/components/button/guidelines/
A6: R005 | B6: Primer | C6: Button | D6: Labels use sentence case, never all caps | E6: P | F6: none | G6: yes | H6: Regex heuristic; proper nouns need exceptions | I6: https://primer.style/product/components/button/guidelines/
A7: R006 | B7: Primer | C7: Button | D7: Do not remove default focus styles | E7: D | F7: axe (partial) | G7: ext | H7: Computed style at runtime | I7: https://primer.style/product/components/button/guidelines/
A8: R007 | B8: Primer | C8: Button | D8: Primary button goes at the end of a ButtonGroup | E8: S | F8: none | G8: yes | H8: Ordering within group | I8: https://primer.style/product/components/button/guidelines/
A9: R008 | B9: Primer | C9: Button | D9: Pair a primary with a default button, not multiple primaries | E9: S | F9: none | G9: yes | H9: Duplicate of cardinality rule, kept for count | I9: https://primer.style/product/components/button/guidelines/
A10: R009 | B10: Primer | C10: Button | D10: An inactive button must respond to click with a dialog explaining why | E10: D | F10: none | G10: ext | H10: Behavioural; needs event tracing | I10: https://primer.style/product/components/button/guidelines/
A11: R010 | B11: Primer | C11: Button | D11: When using an inactive button, something else on the page should explain the outage | E11: I | F11: none | G11: no | H11: Page-level semantics | I11: https://primer.style/product/components/button/guidelines/
A12: R011 | B12: Primer | C12: Button | D12: Multiple selections shown as 'N selected', not comma-separated | E12: P | F12: none | G12: ext | H12: Literal pattern on label text | I12: https://primer.style/product/components/button/guidelines/
... A19: R018 | B19: Primer | C19: ButtonGroup | D19: Do not use ButtonGroup as tab navigation; use UnderlineNav | E19: I | F19: none | G19: no | H19: Purpose-based substitution | I19: https://primer.style/product/components/button-group/guidelines/
A20: R019 | B20: Primer | C20: ButtonGroup | D20: Only group buttons with related functionality | E20: I | F20: none | G20: no | I20: https://primer.style/product/components/button-group/guidelines/
A21: R020 | B21: Primer | C21: IconButton | D21: IconButton must have a tooltip with a text label | E21: S | F21: axe (partial) | G21: yes | H21: Accompaniment; axe catches missing name, not tooltip | I21: https://primer.style/product/components/icon-button/guidelines/
A22: R021 | B22: Primer | C22: IconButton | D22: Only use IconButton when the icon is easily understood | E22: I | F22: none | G22: no | I22: https://primer.style/product/components/icon-button/guidelines/
A23: R022 | B23: Primer | C23: Dialog | D23: Title is required for every dialog | E23: P | F23: none | G23: yes | H23: Required property | I23: https://primer.style/product/components/dialog/guidelines/
A24: R023 | B24: Primer | C24: Dialog | D24: Close button is required and may not be visually hidden | E24: S | F24: none | G24: yes | H24: Required child + property | I24: https://primer.style/product/components/dialog/guidelines/
A25: R024 | B25: Primer | C25: Dialog | D25: Primary footer actions are right-aligned; secondary may sit left | E25: S | F25: none | G25: yes | H25: Ordering by role within footer | I25: https://primer.style/product/components/dialog/guidelines/
A26: R025 | B26: Primer | C26: Dialog | D26: Add a footer divider when the body scrolls | E26: D | F26: none | G26: ext | H26: Depends on rendered overflow | I26: https://primer.style/product/components/dialog/guidelines/
A27: R026 | B27: Primer | C27: Dialog | D27: Backdrop click dismisses, unless the dialog contains a form | E27: S | F27: none | G27: yes | H27: Conditional on containment | I27: https://primer.style/product/components/dialog/guidelines/
A28: R027 | B28: Primer | C28: Dialog | D28: Content stays inside a 16px safe area | E28: V | F28: stylelint (partial) | G28: yes | H28: Spacing token | I28: https://primer.style/product/components/dialog/guidelines/
A29: R028 | B29: Primer | C29: Dialog | D29: Close button sits 8px from the edges | E29: V | F29: none | G29: yes | H29: Spacing token | I29: https://primer.style/product/components/dialog/guidelines/
A30: R029 | B30: Primer | C30: Dialog | D30: Footer buttons always inside the safe area | E30: D | F30: none | G30: ext | H30: Layout result | I30: https://primer.style/product/components/dialog/guidelines/
A31: R030 | B31: Primer | C31: Dialog | D31: Prefer single-column layouts; avoid a whole page inside a dialog | E31: I | F31: none | G31: no | H31: Proxy: multi-column grid inside Dialog | I31: https://primer.style/product/components/dialog/guidelines/
A32: R031 | B32: Primer | C32: Dialog | D32: Avoid side navigation inside a dialog | E32: S | F32: none | G32: yes | H32: Containment: NavList not inside Dialog | I32: https://primer.style/product/components/dialog/guidelines/
A33: R032 | B33: Primer | C33: Dialog | D33: Up to two nested dialogs acceptable; more than three discouraged | E33: S | F33: none | G33: yes | H33: Nesting depth | I33: https://primer.style/product/components/dialog/guidelines/
A34: R033 | B34: Primer | C34: Dialog | D34: Esc closes only the top-most dialog | E34: D | F34: none | G34: ext | H34: Runtime focus/keyboard | I34: https://primer.style/product/components/dialog/guidelines/
... A36: R035 | B36: Primer | C36: Dialog | D36: Dialogs must adapt to narrow viewports | E36: R | F36: none | G36: yes | H36: Responsive transformation | I36: https://primer.style/product/components/dialog/guidelines/
A37: R036 | B37: Primer | C37: Dialog | D37: Centered dialogs keep 16px between frame and viewport | E37: V | F37: none | G37: yes | I37: https://primer.style/product/components/dialog/guidelines/
A38: R037 | B38: Primer | C38: Dialog | D38: Left side sheets reserved for global navigation | E38: I | F38: none | G38: no | H38: Purpose semantics; proxy possible via region role | I38: https://primer.style/product/components/dialog/guidelines/
A39: R038 | B39: Primer | C39: Dialog | D39: Do not use side sheets for create/edit forms | E39: S | F39: none | G39: yes | H39: Containment: form inside position=left/right | I39: https://primer.style/product/components/dialog/guidelines/
A40: R039 | B40: Primer | C40: Dialog | D40: Side sheets must show a backdrop covering global navigation | E40: S | F40: none | G40: yes | H40: Required sibling/overlay | I40: https://primer.style/product/components/dialog/guidelines/
A41: R040 | B41: Primer | C41: Dialog | D41: Only one side sheet at a time | E41: S | F41: none | G41: yes | H41: Cardinality | I41: https://primer.style/product/components/dialog/guidelines/
A42: R041 | B42: Primer | C42: Dialog | D42: Avoid side sheets on non-full-width pages unless a global action | E42: I | F42: none | G42: no | I42: https://primer.style/product/components/dialog/guidelines/
A43: R042 | B43: Primer | C43: Dialog | D43: Bottom sheet is full width and dims the screen | E43: PL | F43: none | G43: yes | H43: Narrow-viewport realisation | I43: https://primer.style/product/components/dialog/guidelines/
A44: R043 | B44: Primer | C44: Dialog | D44: Bottom sheet in landscape has max width 480px, centered | E44: R | F44: none | G44: yes | H44: Breakpoint-conditional value | I44: https://primer.style/product/components/dialog/guidelines/
A45: R044 | B45: Primer | C45: Dialog | D45: Dialogs with input fields must use full-screen variant on narrow viewports | E45: R | F45: none | G45: yes | H45: Conditional on containment + viewport | I45: https://primer.style/product/components/dialog/guidelines/
A46: R045 | B46: Primer | C46: Dialog | D46: Before using extra-large, consider a page instead | E46: I | F46: none | G46: no | I46: https://primer.style/product/components/dialog/guidelines/
A47: R046 | B47: Primer | C47: Dialog | D47: Confirmation dialogs use the larger title size | E47: P | F47: none | G47: yes | H47: Role -> property | I47: https://primer.style/product/components/dialog/guidelines/
...

Sheet Summary
A1: Design-language conformance: classification of documented rules (sample)
A2: All counts below are formulas over the Rules sheet. Edit or add rows there and this sheet updates.
A4: Class | B4: Name | C4: Primer | D4: Carbon | E4: Polaris | F4: Spectrum | G4: GOV.UK | H4: Total | I4: Share
A5: V | B5: Value | C5: =COUNTIFS(Rules!$E$2:$E$213,$A5,Rules!$B$2:$B$213,C$4) -> 3 | D5: =COUNTIFS(Rules!$E$2:$E$213,$A5,Rules!$B$2:$B$213,D$4) -> 13 | E5: =COUNTIFS(Rules!$E$2:$E$213,$A5,Rules!$B$2:$B$213,E$4) -> 2 | F5: =COUNTIFS(Rules!$E$2:$E$213,$A5,Rules!$B$2:$B$213,F$4) -> 2 | G5: =COUNTIFS(Rules!$E$2:$E$213,$A5,Rules!$B$2:$B$213,G$4) -> 0 | H5: =SUM(C5:G5) -> 20 | I5: =H5/H$13 -> 0.094339623
A6: K | B6: Kind | C6: =COUNTIFS(Rules!$E$2:$E$213,$A6,Rules!$B$2:$B$213,C$4) -> 1 | D6: =COUNTIFS(Rules!$E$2:$E$213,$A6,Rules!$B$2:$B$213,D$4) -> 1 | E6: =COUNTIFS(Rules!$E$2:$E$213,$A6,Rules!$B$2:$B$213,E$4) -> 1 | F6: =COUNTIFS(Rules!$E$2:$E$213,$A6,Rules!$B$2:$B$213,F$4) -> 0 | G6: =COUNTIFS(Rules!$E$2:$E$213,$A6,Rules!$B$2:$B$213,G$4) -> 1 | H6: =SUM(C6:G6) -> 4 | I6: =H6/H$13 -> 0.018867925
A7: P | B7: Property | C7: =COUNTIFS(Rules!$E$2:$E$213,$A7,Rules!$B$2:$B$213,C$4) -> 10 | D7: =COUNTIFS(Rules!$E$2:$E$213,$A7,Rules!$B$2:$B$213,D$4) -> 12 | E7: =COUNTIFS(Rules!$E$2:$E$213,$A7,Rules!$B$2:$B$213,E$4) -> 4 | F7: =COUNTIFS(Rules!$E$2:$E$213,$A7,Rules!$B$2:$B$213,F$4) -> 3 | G7: =COUNTIFS(Rules!$E$2:$E$213,$A7,Rules!$B$2:$B$213,G$4) -> 2 | H7: =SUM(C7:G7) -> 31 | I7: =H7/H$13 -> 0.14622642
A8: S | B8: Structural | C8: =COUNTIFS(Rules!$E$2:$E$213,$A8,Rules!$B$2:$B$213,C$4) -> 17 | D8: =COUNTIFS(Rules!$E$2:$E$213,$A8,Rules!$B$2:$B$213,D$4) -> 31 | E8: =COUNTIFS(Rules!$E$2:$E$213,$A8,Rules!$B$2:$B$213,E$4) -> 11 | F8: =COUNTIFS(Rules!$E$2:$E$213,$A8,Rules!$B$2:$B$213,F$4) -> 4 | G8: =COUNTIFS(Rules!$E$2:$E$213,$A8,Rules!$B$2:$B$213,G$4) -> 5 | H8: =SUM(C8:G8) -> 68 | I8: =H8/H$13 -> 0.32075472
A9: PL | B9: Platform | C9: =COUNTIFS(Rules!$E$2:$E$213,$A9,Rules!$B$2:$B$213,C$4) -> 1 | D9: =COUNTIFS(Rules!$E$2:$E$213,$A9,Rules!$B$2:$B$213,D$4) -> 1 | E9: =COUNTIFS(Rules!$E$2:$E$213,$A9,Rules!$B$2:$B$213,E$4) -> 0 | F9: =COUNTIFS(Rules!$E$2:$E$213,$A9,Rules!$B$2:$B$213,F$4) -> 0 | G9: =COUNTIFS(Rules!$E$2:$E$213,$A9,Rules!$B$2:$B$213,G$4) -> 1 | H9: =SUM(C9:G9) -> 3 | I9: =H9/H$13 -> 0.014150943
A10: R | B10: Responsive | C10: =COUNTIFS(Rules!$E$2:$E$213,$A10,Rules!$B$2:$B$213,C$4) -> 3 | D10: =COUNTIFS(Rules!$E$2:$E$213,$A10,Rules!$B$2:$B$213,D$4) -> 1 | E10: =COUNTIFS(Rules!$E$2:$E$213,$A10,Rules!$B$2:$B$213,E$4) -> 1 | F10: =COUNTIFS(Rules!$E$2:$E$213,$A10,Rules!$B$2:$B$213,F$4) -> 1 | G10: =COUNTIFS(Rules!$E$2:$E$213,$A10,Rules!$B$2:$B$213,G$4) -> 0 | H10: =SUM(C10:G10) -> 6 | I10: =H10/H$13 -> 0.028301887
A11: D | B11: Dynamic | C11: =COUNTIFS(Rules!$E$2:$E$213,$A11,Rules!$B$2:$B$213,C$4) -> 11 | D11: =COUNTIFS(Rules!$E$2:$E$213,$A11,Rules!$B$2:$B$213,D$4) -> 17 | E11: =COUNTIFS(Rules!$E$2:$E$213,$A11,Rules!$B$2:$B$213,E$4) -> 1 | F11: =COUNTIFS(Rules!$E$2:$E$213,$A11,Rules!$B$2:$B$213,F$4) -> 1 | G11: =COUNTIFS(Rules!$E$2:$E$213,$A11,Rules!$B$2:$B$213,G$4) -> 2 | H11: =SUM(C11:G11) -> 32 | I11: =H11/H$13 -> 0.1509434
A12: I | B12: Intent | C12: =COUNTIFS(Rules!$E$2:$E$213,$A12,Rules!$B$2:$B$213,C$4) -> 16 | D12: =COUNTIFS(Rules!$E$2:$E$213,$A12,Rules!$B$2:$B$213,D$4) -> 16 | E12: =COUNTIFS(Rules!$E$2:$E$213,$A12,Rules!$B$2:$B$213,E$4) -> 9 | F12: =COUNTIFS(Rules!$E$2:$E$213,$A12,Rules!$B$2:$B$213,F$4) -> 2 | G12: =COUNTIFS(Rules!$E$2:$E$213,$A12,Rules!$B$2:$B$213,G$4) -> 5 | H12: =SUM(C12:G12) -> 48 | I12: =H12/H$13 -> 0.22641509
A13: Total | C13: =SUM(C5:C12) -> 62 | D13: =SUM(D5:D12) -> 92 | E13: =SUM(E5:E12) -> 29 | F13: =SUM(F5:F12) -> 13 | G13: =SUM(G5:G12) -> 16 | H13: =SUM(H5:H12) -> 212 | I13: =SUM(I5:I12) -> 1
A15: Headline figures
A16: Measure | B16: Count | C16: Share of all rules
A17: Statically checkable (V,K,P,S,PL,R) | B17: =SUMPRODUCT((Rules!$E$2:$E$213="V")+(Rules!$E$2:$E$213="K")+(Rules!$E$2:$E$213="P")+(Rules!$E$2:$E$213="S")+(Rules!$E$2:$E$213="PL")+(Rules!$E$2:$E$213="R")) -> 132 | C17: =B17/H13 -> 0.62264151
A18: Dynamically checkable (D) | B18: =COUNTIF(Rules!$E$2:$E$213,"D") -> 32 | C18: =B18/H13 -> 0.1509434
A19: Mechanically checkable, static or dynamic (all but I) | B19: =COUNTIF(Rules!$E$2:$E$213,"<>I") -> 164 | C19: =B19/H13 -> 0.77358491
A20: Intent, not formalisable (I) | B20: =COUNTIF(Rules!$E$2:$E$213,"I") -> 48 | C20: =B20/H13 -> 0.22641509
A21: Checked today by any tool, fully | B21: =SUMPRODUCT((Rules!$F$2:$F$213<>"none")*(ISNUMBER(SEARCH("partial",Rules!$F$2:$F$213))=FALSE())) -> 12 | C21: =B21/H13 -> 0.056603774
A22: Checked today, including partial coverage | B22: =COUNTIF(Rules!$F$2:$F$213,"<>none") -> 22 | C22: =B22/H13 -> 0.10377358
A23: Structural (S) rules checked today by any tool | B23: =COUNTIFS(Rules!$E$2:$E$213,"S",Rules!$F$2:$F$213,"<>none") -> 3 | C23: =B23/H13 -> 0.014150943
A24: Expressible in draft schema as-is | B24: =COUNTIF(Rules!$G$2:$G$213,"yes") -> 119 | C24: =B24/H13 -> 0.56132075
A25: Expressible with schema extension | B25: =COUNTIF(Rules!$G$2:$G$213,"ext") -> 43 | C25: =B25/H13 -> 0.20283019
A26: Verification gap: checkable but unchecked | B26: =B19-B22 -> 142 | C26: =B26/H13 -> 0.66981132
A28: Method note: sample of 3-4 documentation pages per system (button, dialog/modal, one destructive/confirmation pattern). Rules paraphrased; see Source column. Spectrum's site is JS-rendered and Polaris's current docs omit usage guidance, so those two are under-sampled. Classification by the taxonomy in the position paper, applied by a single rater in one pass — expect ±10% on class shares before a second rater.

Sheet Taxonomy
A1: Class | B1: Name | C1: What it constrains | D1: How it is checked
A2: V | B2: Value | C2: Property values must resolve to tokens | D2: Static, local
A3: K | B3: Kind | C3: Node kind allowed/forbidden/deprecated | D3: Static, local
A4: P | B4: Property | C4: Property schema and cross-property rules | D4: Static, local
A5: S | B5: Structural | C5: Cardinality, containment, accompaniment, ordering over the tree | D5: Static, polynomial
A6: PL | B6: Platform | C6: Per-platform / locale realisation | D6: Static given platform
A7: R | B7: Responsive | C7: Viewport- or container-conditional transformation | D7: Static if branches encoded, else render
A8: D | B8: Dynamic | C8: Observable only at runtime (focus, contrast, layout result) | D8: Requires execution
A9: I | B9: Intent | C9: Purpose, taste, reversibility, data semantics | D9: Not formalisable
A11: Other columns
A12: Checked by existing tool? | B12: eslint / stylelint / axe / figma / none. '(partial)' = the tool catches a neighbouring property (e.g. missing accessible name) but not the rule as written.
A13: Expressible in draft schema | B13: yes = the YAML sketch in the position paper can state it; ext = needs a small extension (thresholds, cross-region equality, literal patterns, runtime hooks); no = intent.

Sheet Observations
A1: Contradictions between systems that a shared checker must parameterise, not hard-code:
A2: - Icon position: Carbon = right of label; Polaris = left of label.
A3: - Nested dialogs: Carbon = never; Primer = up to two acceptable, more than three discouraged.
A4: - Primary alignment: Carbon = left on full pages, right in dialogs; GOV.UK = left of form; Primer = right in dialog footers.
A5: - Confirmation for destructive actions: Primer explicitly says NO confirmation for reversible actions; GOV.UK says add a confirmation step for serious ones. Both are conditional on reversibility, which is intent.
A7: Rule shapes that recur across all five systems (candidates for the schema's core vocabulary):
A8: - cardinality(role, scope, max) e.g. one primary per page/dialog/group
A9: - accompaniment(role, requires, scope) e.g. danger trigger requires confirmation; icon-only requires tooltip
A10: - ordering(roles, container) e.g. cancel left, primary right; delete at bottom of list
A11: - containment(kind, not-inside, container) e.g. no data table / tabs / nav / navigating link inside a modal
A12: - sibling-consistency(property, group) e.g. same size, same width, all-or-no icons within a group
A13: - allowed-combination(variants, group) Carbon's explicit 2- and 3-button tables
... A27: - Accessibility tooling (axe) covers a neighbour of many rules (accessible name present) but almost never the design rule itself (tooltip present, label visible).
